I'm sorry, but an uncaught exception occurred.

While running game code:
  File "game/script.rpy", line 32, in script call
    call pre_ch0
  File "game/script-prech0.rpy", line 37, in script
    a "..."
Exception: Sayer 'a' is not defined.

-- Full Traceback ------------------------------------------------------------

Full traceback:
  File "game/script.rpy", line 32, in script call
    call pre_ch0
  File "game/script-prech0.rpy", line 37, in script
    a "..."
  File "/home/marquiskurt/Desktop/renpy-6.99.14.3-sdk/renpy/ast.py", line 624, in execute
    who = eval_who(self.who, self.who_fast)
  File "/home/marquiskurt/Desktop/renpy-6.99.14.3-sdk/renpy/ast.py", line 537, in eval_who
    raise Exception("Sayer '%s' is not defined." % who.encode("utf-8"))
Exception: Sayer 'a' is not defined.

Linux-4.15.0-20-generic-x86_64-with-debian-buster-sid
Ren'Py 6.99.14.3.3347
Doki Doki: The Angel Returns 0.1.0
Sun May 20 19:38:27 2018
